<robot name="mira">
    <link name="base_link">
        <visual>
        <origin rpy="0 0 0" xyz="0 0 0"/>
        <geometry>
            <cylinder radius="0.06" length="0.09"/>
        </geometry>
        
        </visual>
    </link>
    <link name="roll_M1_link">
        <visual>
        <origin xyz ='0 0 0' rpy="0 0 0"/>
        <geometry>
        <cylinder radius="0.01" length="0.005"/>
        </geometry>
        <material name='green'/>
        </visual>
        <inertial>
        <mass value='0.001'/>
        <origin xyz='0 0 0' rpy='0 0 0'/>
        <inertia ixx="2.70833333333e-08" ixy="0.0" ixz="0.0" iyy="2.70833333333e-08" iyz="0.0" izz="5e-08"/>
    </link>
        <gazebo reference="roll_M1_link">
        <kp>1000.0</kp>
        <kd>10.0</kd>
        <mu1>10.0</mu1>
        <mu2>10.0</mu2>
        <material>Gazebo/Red</material>
        </gazebo>
    <joint name="roll_joint" type="revolute">
        <parent link="base_link"/>
        <child link="roll_M1_link"/>
        <origin xyz="0 0 -0.02" rpy="0 0 0"/>
        <limit lower="-0.2" upper="0.2" effort="0.1" velocity="0.005"/>
        <axis xyz="1 0 0"/>
    </joint>
</robot>